<robot name="robot_test">

	<!-- * * * Link Definitions * * * -->

 	<link name="base_link">
		<visual>
		    <origin xyz="0 0 0.0425" rpy="0 0 0"/>
			<geometry>
				<box size="0.4 0.6 0.085"/>
			</geometry>
			<material name="Cyan1">
	       		<color rgba="0 0.9 0.9 1.0"/>
	     	</material>
		</visual>
  		<collision>
          	<origin xyz="0 0 0.0425" rpy="0 0 0"/>
    		<geometry>
      			<box size="0.4 0.6 0.085"/>
          	</geometry>
  		</collision>
  		<inertial>
          	<origin xyz="0 0 0.0425" rpy="0 0 0"/>
      		<mass value="24.072"/>
          	<inertia ixx="0.7366533499999999" ixy="0.0" ixz="0.0" iyy="0.33545335000000004" iyz="0.0" izz="1.0431199999999998"/>
    	</inertial>
	</link>

	<joint name="rightwall_joint" type="fixed">
    	<parent link="base_link"/>
    	<child link="rightwall_link"/>
    	<origin xyz="0 0 0" rpy="0 0 0"/>
	</joint>

	<link name="rightwall_link">
		<visual>
		    <origin xyz="0.205 0 0.15" rpy="0 0 0"/>
			<geometry>
				<box size="0.01 1.4 0.3"/>
			</geometry>
			<material name="Cyan1">
	       		<color rgba="0 0.9 0.9 1.0"/>
	     	</material>
		</visual>
		<collision>
            <origin xyz="0.205 0 0.15" rpy="0 0 0"/>
            <geometry>
				<box size="0.01 1.4 0.3"/>
			</geometry>
        </collision>
        <inertial>
            <origin xyz="0.205 0 0.15" rpy="0 0 0"/>
            <mass value="4.956"/>
            <inertia ixx="0.84665" ixy="0.0" ixz="0.0" iyy="0.0372113" iyz="0.0" izz="0.8095213"/>
        </inertial>
	</link>


	<joint name="leftwall_joint" type="fixed">
    	<parent link="base_link"/>
    	<child link="leftwall_link"/>
    	<origin xyz="0 0 0" rpy="0 0 0"/>
	</joint>


	<link name="leftwall_link">
		<visual>
		    <origin xyz="-0.205 0 0.15" rpy="0 0 0"/>
			<geometry>
				<box size="0.01 1.4 0.3"/>
			</geometry>
			<material name="Cyan1">
	       		<color rgba="0 0.9 0.9 1.0"/>
	     	</material>
		</visual>
        <collision>
            <origin xyz="-0.205 0 0.15" rpy="0 0 0"/>
            <geometry>
				<box size="0.01 1.4 0.3"/>
			</geometry>
        </collision>
        <inertial>
            <origin xyz="-0.205 0 0.15" rpy="0 0 0"/>
            <mass value="4.956"/>
            <inertia ixx="0.84665" ixy="0.0" ixz="0.0" iyy="0.0372113" iyz="0.0" izz="0.8095213"/>
        </inertial>
	</link>

	<link name="striker_body">
		<visual>
		    <origin xyz="0 -0.35 0.125" rpy="0 0 0"/>
			<geometry>
				<box size="0.15 0.10 0.08"/>
			</geometry>
			<material name="Blue2">
				<color rgba="0 0 0.7 1.0"/>
			</material>
		</visual>
        <collision>
            <origin xyz="0 -0.35 0.125" rpy="0 0 0"/>
            <geometry>
				<box size="0.15 0.10 0.08"/>
			</geometry>
        </collision>
        <inertial>
            <origin xyz="0 -0.35 0.125" rpy="0 0 0"/>
            <mass value="1.416"/>
            <inertia ixx="0.0019352" ixy="0.0" ixz="0.0" iyy="0.0034101999999999995" iyz="0.0" izz="0.003835"/>
        </inertial>
	</link>

	<joint name="prismatic_joint" type="prismatic">
    	<parent link="base_link"/>
    	<child link="striker_body"/>
    	<axis xyz="1 0 0" />
        <limit lower="-0.125" upper="0.125" effort="100" velocity="1.0"/>
	</joint>

	<link name="striker_link">
		<visual>
		    <origin xyz="0 -0.3 0.125" rpy="0 0 0"/>
			<geometry>
				<cylinder length="0.0801" radius="0.075"/>
			</geometry>
			<material name="Grey1">
				<color rgba="0.7 0.7 0.7 1.0"/>
			</material>
		</visual>
        <collision>
            <origin xyz="0 -0.3 0.125" rpy="0 0 0"/>
            <geometry>
				<cylinder length="0.0801" radius="0.075"/>
			</geometry>
        </collision>
        <inertial>
            <origin xyz="0 -0.3 0.125" rpy="0 0 0"/>
            <mass value="0.8351"/>
            <inertia ixx="0.00162086020425" ixy="0.0" ixz="0.0" iyy="0.00162086020425" iyz="0.0" izz="0.0023487187499999997"/>
        </inertial>
	</link>

	<joint name="striker_joint" type="prismatic">
    	<parent link="striker_body"/>
    	<child link="striker_link"/>
    	<axis xyz="0 1 0" />
        <limit lower="0" upper="0.015"/>
	</joint>

	<link name="robot_sensor">
		<visual>
		    <origin xyz="0 -0.5 0.01" rpy="0 0 0"/>
			<geometry>
				<box size="0.4 0.4 0.02"/>
			</geometry>
			<material name="Black">
	       		<color rgba="0.2 0.2 0.2 1.0"/>
	     	</material>
		</visual>
        <collision>
            <origin xyz="0 -0.5 0.01" rpy="0 0 0"/>
            <geometry>
				<box size="0.4 0.4 0.02"/>
			</geometry>
        </collision>
        <inertial>
            <origin xyz="0 -0.5 0.01" rpy="0 0 0"/>
            <mass value="3.7760000000000007"/>
            <inertia ixx="0.050472533333333354" ixy="0.0" ixz="0.0" iyy="0.050472533333333354" iyz="0.0" izz="0.10069333333333337"/>
        </inertial>
	</link>

	<joint name="robot_sensor_joint" type="fixed">
    	<parent link="base_link"/>
    	<child link="robot_sensor"/>
    	<origin xyz="0 0 0" rpy="0 0 0"/>
	</joint>

	<link name="player_sensor">
		<visual>
		    <origin xyz="0 0.5 0.01" rpy="0 0 0"/>
			<geometry>
				<box size="0.4 0.4 0.02"/>
			</geometry>
			<material name="Black">
	       		<color rgba="0.2 0.2 0.2 1.0"/>
	     	</material>
		</visual>
        <collision>
            <origin xyz="0 0.5 0.01" rpy="0 0 0"/>
            <geometry>
				<box size="0.4 0.4 0.02"/>
			</geometry>
        </collision>
        <inertial>
            <origin xyz="0 0.5 0.01" rpy="0 0 0"/>
            <mass value="3.7760000000000007"/>
            <inertia ixx="0.050472533333333354" ixy="0.0" ixz="0.0" iyy="0.050472533333333354" iyz="0.0" izz="0.10069333333333337"/>
        </inertial>
	</link>

	<joint name="player_sensor_joint" type="fixed">
    	<parent link="base_link"/>
    	<child link="player_sensor"/>
    	<origin xyz="0 0 0" rpy="0 0 0"/>
	</joint>

	<link name="robotwall_link">
		<visual>
		    <origin xyz="0 -0.7 0.15" rpy="0 0 0"/>
			<geometry>
				<box size="0.4 0.01 0.3"/>
			</geometry>
			<material name="Cyan1">
	       		<color rgba="0 0.9 0.9 1.0"/>
	     	</material>
		</visual>
        <collision>
            <origin xyz="0 -0.7 0.15" rpy="0 0 0"/>
            <geometry>
				<box size="0.4 0.01 0.3"/>
			</geometry>
        </collision>
        <inertial>
            <origin xyz="0 -0.7 0.15" rpy="0 0 0"/>
            <mass value="1.416"/>
            <inertia ixx="0.010631799999999999" ixy="0.0" ixz="0.0" iyy="0.0295" iyz="0.0" izz="0.0188918"/>
        </inertial>
	</link>

	<joint name="robotwall_joint" type="fixed">
    	<parent link="base_link"/>
    	<child link="robotwall_link"/>
    	<origin xyz="0 0 0" rpy="0 0 0"/>
	</joint>

	<link name="playerwall_link">
		<visual>
		    <origin xyz="0 0.7 0.15" rpy="0 0 0"/>
			<geometry>
				<box size="0.4 0.01 0.3"/>
			</geometry>
			<material name="Cyan1">
	       		<color rgba="0 0.9 0.9 1.0"/>
	     	</material>
		</visual>
        <collision>
            <origin xyz="0 0.7 0.15" rpy="0 0 0"/>
            <geometry>
				<box size="0.4 0.01 0.3"/>
			</geometry>
        </collision>
        <inertial>
            <origin xyz="0 0.7 0.15" rpy="0 0 0"/>
            <mass value="1.416"/>
            <inertia ixx="0.010631799999999999" ixy="0.0" ixz="0.0" iyy="0.0295" iyz="0.0" izz="0.0188918"/>
        </inertial>
	</link>

	<joint name="playerwall_joint" type="fixed">
    	<parent link="base_link"/>
    	<child link="playerwall_link"/>
    	<origin xyz="0 0 0" rpy="0 0 0"/>
	</joint>

</robot>